Workbook
Name abf_tower_temperature: Various!$R$17
Name aeration_basin_do_north_avg_handheld: 'Basin DO'!$J$4
Name aeration_basin_do_north_avg_probes: 'Basin DO'!$J$5
Name aeration_basin_do_south_avg_handheld: 'Basin DO'!$J$9
Name aeration_basin_do_south_avg_probes: 'Basin DO'!$J$10
Name aeration_basin_tempature: Various!$R$18
Name basin_flow_total: Clarifier!$F$31
Name basin_total_flow: Clarifier!$F$31
Name clarifier_flow_total: Clarifier!$F$33
Name clarifier_underflow_total: Clarifier!$F$32
Name date: Print!$C$2
Name inf_flow_avg: Hourly!$C$27
Name inf_flow_max: Hourly!$C$28
Name lagoon_sludge_temp_avg: Lagoon!$K$8
Name max_pH: Print!$C$13
Name min_pH: Print!#REF!
Name paa_daily_avg: 'PAA and pH'!$D$8
Name paa_post_avg: 'PAA and pH'!$D$9
Name ph_daily_avg: 'PAA and pH'!$D$18
Name wasting_average: Hourly!$H$27

Sheet Hourly
B2: TIME | C2: Influent Flow (MGD) | D2: Effuent Flow (MGD) | E2: Before WET WELL | F2: After WET WELL | G2: Under flow | H2: TOT WAS | I2: RAW SEWAGE PUMPS | J2: RETURN SLUDGE PUMPS | K2: PRI. PUMPS | L2: RAS | M2: Screws # ON | N2: ABF # ON | O2: Blowers # ON | P2: AMPS | Q2: KW | R2: Potable Water Pressure | S2: Eff TSS | T2: H2S | U2: Final COD (mg/L)
B3: 0
B4: 0.041666667
B5: 0.083333333
B6: 0.125
B7: 0.16666667
B8: 0.20833333
B9: 0.25
B10: 0.29166667
B11: 0.33333333
B12: 0.375
B13: 0.41666667
B14: 0.45833333
... B22: 0.79166667
B23: 0.83333333 | Y23: `
B24: 0.875
B25: 0.91666667
B26: 0.95833333
B27: DAILY AVG. | C27: =IFERROR(AVERAGE(C3:C26),"Empty") -> Empty | D27: =IFERROR(AVERAGE(D3:D26),"Empty") -> Empty | E27: =IFERROR(AVERAGE(E3:E26),"Empty") -> Empty | F27: =IFERROR(AVERAGE(F3:F26),"Empty") -> Empty | G27: =IFERROR(AVERAGE(G3:G26),"Empty") -> Empty | H27: =IFERROR(AVERAGE(H3:H26),"Empty") -> Empty | I27: - | J27: - | K27: - | L27: =IFERROR(AVERAGE(L3:L26),"Empty") -> Empty | M27: =IFERROR(AVERAGE(M3:M26),"Empty") -> Empty | N27: =IFERROR(AVERAGE(N3:N26),"Empty") -> Empty | O27: =IFERROR(AVERAGE(O3:O26),"Empty") -> Empty | P27: =IFERROR(AVERAGE(P3:P26),"Empty") -> Empty | Q27: =IFERROR(AVERAGE(Q3:Q26),"Empty") -> Empty | R27: =IFERROR(AVERAGE(R3:R26),"Empty") -> Empty | S27: =IFERROR(AVERAGE(S3:S26),"Empty") -> Empty | ... U27: =IFERROR(AVERAGE(U3:U26),"Empty") -> Empty
B28: MAX | C28: =MAX(C3:C26) -> 0 | D28: =MAX(D3:D26) -> 0 | E28: =MAX(E3:E26) -> 0 | F28: =MAX(F3:F26) -> 0 | G28: =MAX(G3:G26) -> 0 | H28: =MAX(H3:H26) -> 0 | K28: =MAX(K3:K26) -> 0 | L28: =MAX(L3:L26) -> 0 | M28: =MAX(M3:M26) -> 0 | N28: =MAX(N3:N26) -> 0 | O28: =MAX(O3:O26) -> 0 | P28: =MAX(P3:P26) -> 0 | Q28: =MAX(Q3:Q26) -> 0 | R28: =MAX(R3:R26) -> 0 | ... U28: =MAX(U3:U26) -> 0
B29: MIN | C29: =MIN(C3:C26) -> 0 | D29: =MIN(D3:D26) -> 0 | E29: =MIN(E3:E26) -> 0 | F29: =MIN(F3:F26) -> 0 | G29: =MIN(G3:G26) -> 0 | H29: =MIN(H3:H26) -> 0 | K29: =MIN(K3:K26) -> 0 | L29: =MIN(L3:L26) -> 0 | M29: =MIN(M3:M26) -> 0 | N29: =MIN(N3:N26) -> 0 | O29: =MIN(O3:O26) -> 0 | P29: =MIN(P3:P26) -> 0 | Q29: =MIN(Q3:Q26) -> 0 | R29: =MIN(R3:R26) -> 0 | ... U29: =MIN(U3:U26) -> 0
B30: Total | Q30: =SUM(Q$3:Q$26) -> 0

Sheet Clarifier
C2: NORTH BASIN | K2: SOUTH BASIN | S2: NORTH CLAR. | X2: SOUTH CLAR. | AC2: NORTH RAS | AH2: SOUTH RAS
B3: TIME | C3: 2 | D3: 4 | E3: 6 | F3: 8 | G3: 10 | H3: 12 | I3: 14 | K3: 2 | L3: 4 | M3: 6 | N3: 8 | O3: 10 | P3: 12 | Q3: 14 | S3: 1 | T3: 2 | U3: 3 | V3: 4 | X3: 1 | Y3: 2 | Z3: 3 | AA3: 4 | AC3: 1 | AD3: 2 | AE3: 3 | AF3: 4 | AH3: 1 | AI3: 2 | AJ3: 3 | AK3: 4
B4: 0
B5: 0.041666667
B6: 0.083333333
B7: 0.125
B8: 0.16666667
B9: 0.20833333
B10: 0.25
B11: 0.29166667
B12: 0.33333333
B13: 0.375
B14: 0.41666667
B15: 0.45833333
... B27: 0.95833333
B28: DAILY AVG. | C28: =IFERROR(AVERAGEA(C$4:C$27),"Empty") -> Empty | D28: =IFERROR(AVERAGEA(D$4:D$27),"Empty") -> Empty | E28: =IFERROR(AVERAGEA(E$4:E$27),"Empty") -> Empty | F28: =IFERROR(AVERAGEA(F$4:F$27),"Empty") -> Empty | G28: =IFERROR(AVERAGEA(G$4:G$27),"Empty") -> Empty | H28: =IFERROR(AVERAGEA(H$4:H$27),"Empty") -> Empty | I28: =IFERROR(AVERAGEA(I$4:I$27),"Empty") -> Empty | K28: =IFERROR(AVERAGEA(K$4:K$27),"Empty") -> Empty | L28: =IFERROR(AVERAGEA(L$4:L$27),"Empty") -> Empty | M28: =IFERROR(AVERAGEA(M$4:M$27),"Empty") -> Empty | N28: =IFERROR(AVERAGEA(N$4:N$27),"Empty") -> Empty | O28: =IFERROR(AVERAGEA(O$4:O$27),"Empty") -> Empty | P28: =IFERROR(AVERAGEA(P$4:P$27),"Empty") -> Empty | Q28: =IFERROR(AVERAGEA(Q$4:Q$27),"Empty") -> Empty | S28: =IFERROR(AVERAGEA(S$4:S$27),"Empty") -> Empty | T28: =IFERROR(AVERAGEA(T$4:T$27),"Empty") -> Empty | U28: =IFERROR(AVERAGEA(U$4:U$27),"Empty") -> Empty | V28: =IFERROR(AVERAGEA(V$4:V$27),"Empty") -> Empty | X28: =IFERROR(AVERAGEA(X$4:X$27),"Empty") -> Empty | Y28: =IFERROR(AVERAGEA(Y$4:Y$27),"Empty") -> Empty | Z28: =IFERROR(AVERAGEA(Z$4:Z$27),"Empty") -> Empty | AA28: =IFERROR(AVERAGEA(AA$4:AA$27),"Empty") -> Empty | AC28: =IFERROR(AVERAGEA(AC$4:AC$27),"Empty") -> Empty | AD28: =IFERROR(AVERAGEA(AD$4:AD$27),"Empty") -> Empty | AE28: =IFERROR(AVERAGEA(AE$4:AE$27),"Empty") -> Empty | AF28: =IFERROR(AVERAGEA(AF$4:AF$27),"Empty") -> Empty | AH28: =IFERROR(AVERAGEA(AH$4:AH$27),"Empty") -> Empty | AI28: =IFERROR(AVERAGEA(AI$4:AI$27),"Empty") -> Empty | AJ28: =IFERROR(AVERAGEA(AJ$4:AJ$27),"Empty") -> Empty | AK28: =IFERROR(AVERAGEA(AK$4:AK$27),"Empty") -> Empty
B29: DAILY TOTAL | C29: =IFERROR(SUM(C$4:C$27),"Empty") -> 0 | D29: =IFERROR(SUM(D$4:D$27),"Empty") -> 0 | E29: =IFERROR(SUM(E$4:E$27),"Empty") -> 0 | F29: =IFERROR(SUM(F$4:F$27),"Empty") -> 0 | G29: =IFERROR(SUM(G$4:G$27),"Empty") -> 0 | H29: =IFERROR(SUM(H$4:H$27),"Empty") -> 0 | I29: =IFERROR(SUM(I$4:I$27),"Empty") -> 0 | K29: =IFERROR(SUM(K$4:K$27),"Empty") -> 0 | L29: =IFERROR(SUM(L$4:L$27),"Empty") -> 0 | M29: =IFERROR(SUM(M$4:M$27),"Empty") -> 0 | N29: =IFERROR(SUM(N$4:N$27),"Empty") -> 0 | O29: =IFERROR(SUM(O$4:O$27),"Empty") -> 0 | P29: =IFERROR(SUM(P$4:P$27),"Empty") -> 0 | Q29: =IFERROR(SUM(Q$4:Q$27),"Empty") -> 0 | S29: =IFERROR(SUM(S$4:S$27),"Empty") -> 0 | T29: =IFERROR(SUM(T$4:T$27),"Empty") -> 0 | U29: =IFERROR(SUM(U$4:U$27),"Empty") -> 0 | V29: =IFERROR(SUM(V$4:V$27),"Empty") -> 0 | X29: =IFERROR(SUM(X$4:X$27),"Empty") -> 0 | Y29: =IFERROR(SUM(Y$4:Y$27),"Empty") -> 0 | Z29: =IFERROR(SUM(Z$4:Z$27),"Empty") -> 0 | AA29: =IFERROR(SUM(AA$4:AA$27),"Empty") -> 0 | AC29: =IFERROR(SUM(AC$4:AC$27),"Empty") -> 0 | AD29: =IFERROR(SUM(AD$4:AD$27),"Empty") -> 0 | AE29: =IFERROR(SUM(AE$4:AE$27),"Empty") -> 0 | AF29: =IFERROR(SUM(AF$4:AF$27),"Empty") -> 0 | AH29: =IFERROR(SUM(AH$4:AH$27),"Empty") -> 0 | AI29: =IFERROR(SUM(AI$4:AI$27),"Empty") -> 0 | AJ29: =IFERROR(SUM(AJ$4:AJ$27),"Empty") -> 0 | AK29: =IFERROR(SUM(AK$4:AK$27),"Empty") -> 0
E31: Basin Total Flow | F31: =IFERROR(SUM(C29:Q29),"Empty") -> 0
E32: Clarifier Total Underflow (RAS) | F32: =IFERROR(SUM(AC28:AK28),"Empty") -> 0
E33: Secondary Clarifier Total Flow | F33: =IFERROR(SUM(S28:AA28),"Empty") -> 0

Sheet Outfall
B2: Operator Initials | C2: Time** | D2: Safe to make Observation? | F2: Floatable Present ? | H2: Scum Present? | J2: Foam Present? | L2: Oily Slick Present?
D4: Yes | E4: No | F4: Yes | G4: No | H4: Yes | I4: No | J4: Yes | K4: No | L4: Yes | M4: No

Sheet PAA and pH
D3: Shift: 11pm-7am | H3: Shift: 7am-3pm | L3: Shift: 3pm-11pm
C4: Disinfection Tank Location | D4: PRE | E4: MID | F4: Post | H4: PRE | I4: MID | J4: Post | L4: PRE | M4: MID | N4: Post
C5: PAA Residual
C6: PAA Shift Average | D6: =IFERROR(AVERAGEA(D5:F5),"Empty") -> Empty | H6: =IFERROR(AVERAGEA(H5:J5),"Empty") -> Empty | L6: =IFERROR(AVERAGEA(L5:N5),"Empty") -> Empty
C8: PAA Daily Average | D8: =IFERROR(AVERAGE(H6,L6,D6),"Empty") -> Empty
C9: PAA Post Average | D9: =IFERROR(AVERAGEA(J5,N5,F5),"Empty") -> Empty
D13: Shift: 11pm-7am | H13: Shift: 7am-3pm | L13: Shift: 3pm-11pm
C14: Location | D14: Pri Sldg | E14: Sec Dwt | F14: Return Sludge | H14: Pri Sldg | I14: Sec Dwt | J14: Return Sludge | L14: Pri Sldg | M14: Sec Dwt | N14: Return Sludge
C15: pH
C16: ShpH ift Average | D16: =IFERROR(AVERAGE(D15:F15),"Empty") -> Empty | H16: =IFERROR(AVERAGE(H15:J15),"Empty") -> Empty | L16: =IFERROR(AVERAGE(L15:N15),"Empty") -> Empty
C18: pH Daily Average | D18: =IFERROR(AVERAGE(H16,L16,D16),"Empty") -> Empty

Sheet Lagoon
C2: 11pm-7am | D2: 7am-3pm | E2: 3pm-11pm | G2: Lagoon Sludge Temp
B3: FLARE #1 | G3: Shift | H3: 2A | J3: 2C | K3: 1
B4: FLARE #2 | G4: 40854
B5: FLARE #3 | G5: 40727
B6: FLARE #4 | G6: 40613
B7: FLARE #5 | G7: AVG | H7: =IFERROR(AVERAGE(H4:H6),"Empty") -> Empty | I7: =IFERROR(AVERAGE(I4:I6),"Empty") -> Empty | J7: =IFERROR(AVERAGE(J4:J6),"Empty") -> Empty | K7: =IFERROR(AVERAGE(K4:K6),"Empty") -> Empty
G8: Avg. of All Lagoons Temp: | K8: =IFERROR(AVERAGE(H7:K7),"Empty") -> Empty

Sheet Various
B2: Primary Blankets | J2: Settlometer | Q2: # In Service
B3: TIME | C3: FLOW | D3: #1 | E3: #2 | F3: #3 | G3: #4 | H3: AVG | J3: Time | K3: North | L3: South | Q3: Pri. Clarifiers
B4: hh:mm | H4: =IFERROR(AVERAGE(D4:G4),"Empty") -> Empty | J4: 5 | Q4: ABF Towers
B5: hh:mm | H5: =IFERROR(AVERAGE(D5:G5),"Empty") -> Empty | J5: 10 | Q5: Lrg. Basin
B6: hh:mm | H6: =IFERROR(AVERAGE(D6:G6),"Empty") -> Empty | J6: 15 | Q6: Sm. Basin
C7: . | J7: 20 | Q7: Total Basins
J8: 25 | Q8: Sec. Clarifiers
J9: 30 | Q9: Blowers
B12: Secondary Blankets | U12: Blower | V12: 1 | W12: 2C | X12: Avg H2S
D13: North | I13: South | U13: Volume of Biogas
B14: TIME ** | C14: Inf Flow | D14: #1 | E14: #2 | F14: #3 | G14: #4 | H14: #5 | I14: #1 | J14: #2 | K14: #3 | L14: #4 | M14: #5 | N14: AVG
B15: hh:mm | N15: =IFERROR(AVERAGE(D15:L15),"Empty") -> Empty
B16: hh:mm | N16: =IFERROR(AVERAGE(D16:L16),"Empty") -> Empty | Q16: Temperature | U16: Sludge pH | V16: RAS | W16: Primary
B17: hh:mm | N17: =IFERROR(AVERAGE(D17:L17),"Empty") -> Empty | Q17: TOWERS | U17: Max
B18: ** All Blanket times must be entered in hh:mm format military time | N18: =IFERROR(SUM(N15:N17),"Empty") -> 0 | Q18: AERA BASINS | U18: Min

Sheet Basin DO
C2: Basin D.O. Profile - North
C3: 2 | D3: 4 | E3: 6 | F3: 8 | G3: 10 | H3: 12 | I3: 14 | J3: AVG
B4: Handheld | J4: =IFERROR(AVERAGE(C4:I4),"Empty") -> Empty
B5: Probes | J5: =IFERROR(AVERAGE(C5:I5),"Empty") -> Empty
C7: Basin D.O. Profile - South
C8: 2 | D8: 4 | E8: 6 | F8: 8 | G8: 10 | H8: 12 | I8: 14 | J8: AVG
B9: Handheld | J9: =IFERROR(AVERAGE(C9:I9),"Empty") -> Empty
B10: Probes | J10: =IFERROR(AVERAGE(C10:I10),"Empty") -> Empty

Sheet Print
B2: Date | C2: MM/DD/YYYY
B4: Flows
B5: Influent Avg Flow | C5: =inf_flow_avg -> Empty
B6: Influent Max Flow | C6: =inf_flow_max -> 0
B7: Total Basin Flow | C7: =basin_flow_total -> 0
B8: Total Clarifier Flow | C8: =clarifier_flow_total -> 0
B9: Total Underflow | C9: =clarifier_underflow_total -> 0
B10: Wasting Avg | C10: =wasting_average -> Empty
B12: Plant pH
B13: Avg | C13: =ph_daily_avg -> Empty
B15: Power
B16: Max KW | C16: =Hourly!Q28 -> 0
B17: Total KW | C17: =Hourly!Q30 -> 0
B19: Temperatures
B20: Lagoon sludge temp | C20: =lagoon_sludge_temp_avg -> Empty
B21: ABF tower temp | C21: =abf_tower_temperature -> 0
B22: Aeration Basin Temp | C22: =aeration_basin_tempature -> 0
B24: PAA
B25: PAA daily average | C25: =paa_daily_avg -> Empty
B26: PAA post average | C26: =paa_post_avg -> Empty
B28: Basin DO Profile
B29: North handheld | C29: =aeration_basin_do_north_avg_handheld -> Empty
B30: South handheld | C30: =aeration_basin_do_south_avg_handheld -> Empty
B31: North permanent | C31: =aeration_basin_do_north_avg_probes -> Empty
B32: South permanent | C32: =aeration_basin_do_south_avg_probes -> Empty

Sheet Hourly Data
A1: Sampled Date | B1: Parameter | C1: Reported Result | D1: Unit | E1: Sample Location
A2: =Various!#REF! -> #REF! | B2: Hourly Flow (00:00) | C2: =IF(Hourly!C3="","",Hourly!C3) | D2: MGD | E2: TEM Influent
A3: =Various!#REF! -> #REF! | B3: Hourly Flow (01:00) | C3: =IF(Hourly!C5="","",Hourly!C5) | D3: MGD | E3: TEM Influent
A4: =Various!#REF! -> #REF! | B4: Hourly Flow (02:00) | C4: =IF(Hourly!#REF!="","",Hourly!#REF!) -> #REF! | D4: MGD | E4: TEM Influent
A5: =Various!#REF! -> #REF! | B5: Hourly Flow (03:00) | C5: =IF(Hourly!C6="","",Hourly!C6) | D5: MGD | E5: TEM Influent
A6: =Various!#REF! -> #REF! | B6: Hourly Flow (04:00) | C6: =IF(Hourly!C7="","",Hourly!C7) | D6: MGD | E6: TEM Influent
A7: =Various!#REF! -> #REF! | B7: Hourly Flow (05:00) | C7: =IF(Hourly!C8="","",Hourly!C8) | D7: MGD | E7: TEM Influent
A8: =Various!#REF! -> #REF! | B8: Hourly Flow (06:00) | C8: =IF(Hourly!C9="","",Hourly!C9) | D8: MGD | E8: TEM Influent
A9: =Various!#REF! -> #REF! | B9: Hourly Flow (07:00) | C9: =IF(Hourly!C10="","",Hourly!C10) | D9: MGD | E9: TEM Influent
A10: =Various!#REF! -> #REF! | B10: Hourly Flow (08:00) | C10: =IF(Hourly!C11="","",Hourly!C11) | D10: MGD | E10: TEM Influent
A11: =Various!#REF! -> #REF! | B11: Hourly Flow (09:00) | C11: =IF(Hourly!C12="","",Hourly!C12) | D11: MGD | E11: TEM Influent
A12: =Various!#REF! -> #REF! | B12: Hourly Flow (10:00) | C12: =IF(Hourly!H35="","",Hourly!H35) | D12: MGD | E12: TEM Influent
A13: =Various!#REF! -> #REF! | B13: Hourly Flow (11:00) | C13: =IF(Hourly!#REF!="","",Hourly!#REF!) -> #REF! | D13: MGD | E13: TEM Influent
A14: =Various!#REF! -> #REF! | B14: Hourly Flow (12:00) | C14: =IF(Hourly!C14="","",Hourly!C14) | D14: MGD | E14: TEM Influent
A15: =Various!#REF! -> #REF! | B15: Hourly Flow (13:00) | C15: =IF(Hourly!C16="","",Hourly!C16) | D15: MGD | E15: TEM Influent
A16: =Various!#REF! -> #REF! | B16: Hourly Flow (14:00) | C16: =IF(Hourly!C17="","",Hourly!C17) | D16: MGD | E16: TEM Influent
A17: =Various!#REF! -> #REF! | B17: Hourly Flow (15:00) | C17: =IF(Hourly!C18="","",Hourly!C18) | D17: MGD | E17: TEM Influent
A18: =Various!#REF! -> #REF! | B18: Hourly Flow (16:00) | C18: =IF(Hourly!C19="","",Hourly!C19) | D18: MGD | E18: TEM Influent
A19: =Various!#REF! -> #REF! | B19: Hourly Flow (17:00) | C19: =IF(Hourly!C20="","",Hourly!C20) | D19: MGD | E19: TEM Influent
A20: =Various!#REF! -> #REF! | B20: Hourly Flow (18:00) | C20: =IF(Hourly!C21="","",Hourly!C21) | D20: MGD | E20: TEM Influent
A21: =Various!#REF! -> #REF! | B21: Hourly Flow (19:00) | C21: =IF(Hourly!C22="","",Hourly!C22) | D21: MGD | E21: TEM Influent
A22: =Various!#REF! -> #REF! | B22: Hourly Flow (20:00) | C22: =IF(Hourly!C23="","",Hourly!C23) | D22: MGD | E22: TEM Influent
A23: =Various!#REF! -> #REF! | B23: Hourly Flow (21:00) | C23: =IF(Hourly!C24="","",Hourly!C24) | D23: MGD | E23: TEM Influent
A24: =Various!#REF! -> #REF! | B24: Hourly Flow (22:00) | C24: =IF(Hourly!C25="","",Hourly!C25) | D24: MGD | E24: TEM Influent
A25: =Various!#REF! -> #REF! | B25: Hourly Flow (23:00) | C25: =IF(Hourly!C26="","",Hourly!C26) | D25: MGD | E25: TEM Influent

Sheet Data
A1: Sampled Date | B1: Parameter | C1: Reported Result | D1: Unit | E1: Sample Location | F1: Shift | G1: Time | H1: Instrument
A2: =Various!#REF! -> #REF! | B2: Blankets | C2: =IF(Various!E4= "","",Various!E4) | D2: Feet | E2: TEM Primary Clarifier #1 | F2: =IF(AND(G2>=0.291,G2<0.625),"7 to 3",IF(AND(G2>=0.625,G2<0.958334),"3 to 11",IF(G2>=0.958334,"11 to 7",IF(G2<0.291,"11 to 7","")))) -> #VALUE! | G2: =VALUE(Various!$B$15) -> #VALUE!
A3: =Various!#REF! -> #REF! | B3: Blankets | C3: =IF(Various!D5= "","",Various!D5) | D3: Feet | E3: TEM Primary Clarifier #1 | F3: =IF(AND(G3>=0.291,G3<0.625),"7 to 3",IF(AND(G3>=0.625,G3<0.958334),"3 to 11",IF(G3>=0.958334,"11 to 7",IF(G3<0.291,"11 to 7","")))) -> #VALUE! | G3: =VALUE(Various!$B$5) -> #VALUE!
A4: =Various!#REF! -> #REF! | B4: Blankets | C4: =IF(Various!D6= "","",Various!D6) | D4: Feet | E4: TEM Primary Clarifier #1 | F4: =IF(AND(G4>=0.291,G4<0.625),"7 to 3",IF(AND(G4>=0.625,G4<0.958334),"3 to 11",IF(G4>=0.958334,"11 to 7",IF(G4<0.291,"11 to 7","")))) -> #VALUE! | G4: =VALUE(Various!$B$5) -> #VALUE!
A5: =Various!#REF! -> #REF! | B5: Blankets | C5: =IF(Various!G4= "","",Various!G4) | D5: Feet | E5: TEM Primary Clarifier #2 | F5: =IF(AND(G5>=0.291,G5<0.625),"7 to 3",IF(AND(G5>=0.625,G5<0.958334),"3 to 11",IF(G5>=0.958334,"11 to 7",IF(G5<0.291,"11 to 7","")))) -> #VALUE! | G5: =VALUE(Various!$B$15) -> #VALUE!
A6: =Various!#REF! -> #REF! | B6: Blankets | C6: =IF(Various!E5= "","",Various!E5) | D6: Feet | E6: TEM Primary Clarifier #2 | F6: =IF(AND(G6>=0.291,G6<0.625),"7 to 3",IF(AND(G6>=0.625,G6<0.958334),"3 to 11",IF(G6>=0.958334,"11 to 7",IF(G6<0.291,"11 to 7","")))) -> #VALUE! | G6: =VALUE(Various!$B$5) -> #VALUE!
A7: =Various!#REF! -> #REF! | B7: Blankets | C7: =IF(Various!E6= "","",Various!E6) | D7: Feet | E7: TEM Primary Clarifier #2 | F7: =IF(AND(G7>=0.291,G7<0.625),"7 to 3",IF(AND(G7>=0.625,G7<0.958334),"3 to 11",IF(G7>=0.958334,"11 to 7",IF(G7<0.291,"11 to 7","")))) -> #VALUE! | G7: =VALUE(Various!$B$5) -> #VALUE!
A8: =Various!#REF! -> #REF! | B8: Blankets | C8: =IF(Various!#REF!= "","",Various!#REF!) -> #REF! | D8: Feet | E8: TEM Primary Clarifier #3 | F8: =IF(AND(G8>=0.291,G8<0.625),"7 to 3",IF(AND(G8>=0.625,G8<0.958334),"3 to 11",IF(G8>=0.958334,"11 to 7",IF(G8<0.291,"11 to 7","")))) -> #VALUE! | G8: =VALUE(Various!$B$15) -> #VALUE!
A9: =Various!#REF! -> #REF! | B9: Blankets | C9: =IF(Various!F5= "","",Various!F5) | D9: Feet | E9: TEM Primary Clarifier #3 | F9: =IF(AND(G9>=0.291,G9<0.625),"7 to 3",IF(AND(G9>=0.625,G9<0.958334),"3 to 11",IF(G9>=0.958334,"11 to 7",IF(G9<0.291,"11 to 7","")))) -> #VALUE! | G9: =VALUE(Various!$B$5) -> #VALUE!
A10: =Various!#REF! -> #REF! | B10: Blankets | C10: =IF(Various!F6= "","",Various!F6) | D10: Feet | E10: TEM Primary Clarifier #3 | F10: =IF(AND(G10>=0.291,G10<0.625),"7 to 3",IF(AND(G10>=0.625,G10<0.958334),"3 to 11",IF(G10>=0.958334,"11 to 7",IF(G10<0.291,"11 to 7","")))) -> #VALUE! | G10: =VALUE(Various!$B$5) -> #VALUE!
A11: =Various!#REF! -> #REF! | B11: Blankets | C11: =IF(Various!F7= "","",Various!F7) | D11: Feet | E11: TEM Primary Clarifier #4 | F11: =IF(AND(G11>=0.291,G11<0.625),"7 to 3",IF(AND(G11>=0.625,G11<0.958334),"3 to 11",IF(G11>=0.958334,"11 to 7",IF(G11<0.291,"11 to 7","")))) -> #VALUE! | G11: =VALUE(Various!$B$15) -> #VALUE!
A12: =Various!#REF! -> #REF! | B12: Blankets | C12: =IF(Various!G5= "","",Various!G5) | D12: Feet | E12: TEM Primary Clarifier #4 | F12: =IF(AND(G12>=0.291,G12<0.625),"7 to 3",IF(AND(G12>=0.625,G12<0.958334),"3 to 11",IF(G12>=0.958334,"11 to 7",IF(G12<0.291,"11 to 7","")))) -> #VALUE! | G12: =VALUE(Various!$B$5) -> #VALUE!
A13: =Various!#REF! -> #REF! | B13: Blankets | C13: =IF(Various!G6= "","",Various!G6) | D13: Feet | E13: TEM Primary Clarifier #4 | F13: =IF(AND(G13>=0.291,G13<0.625),"7 to 3",IF(AND(G13>=0.625,G13<0.958334),"3 to 11",IF(G13>=0.958334,"11 to 7",IF(G13<0.291,"11 to 7","")))) -> #VALUE! | G13: =VALUE(Various!$B$5) -> #VALUE!
A14: =Various!#REF! -> #REF! | B14: Blankets | C14: =IF(Various!E15="","",Various!E15) | D14: Feet | E14: TEM 1N Secondary Clarifier | F14: =IF(AND(G14>=0.291,G14<0.625),"7 to 3",IF(AND(G14>=0.625,G14<0.958334),"3 to 11",IF(G14>=0.958334,"11 to 7",IF(G14<0.291,"11 to 7","")))) -> 11 to 7 | G14: =VALUE(Various!$B$7) -> 0
A15: =Various!#REF! -> #REF! | B15: Blankets | C15: =IF(Various!D15="","",Various!D15) | D15: Feet | E15: TEM 1N Secondary Clarifier | F15: 7 to 3 | G15: =VALUE(Various!$B$17) -> #VALUE!
A16: =Various!#REF! -> #REF! | B16: Blankets | C16: =IF(Various!D17="","",Various!D17) | D16: Feet | E16: TEM 1N Secondary Clarifier | F16: =IF(AND(G16>=0.291,G16<0.625),"7 to 3",IF(AND(G16>=0.625,G16<0.958334),"3 to 11",IF(G16>=0.958334,"11 to 7",IF(G16<0.291,"11 to 7","")))) -> #VALUE! | G16: =VALUE(Various!$B$17) -> #VALUE!
A17: =Various!#REF! -> #REF! | B17: Blankets | C17: =IF(Various!E15="","",Various!E15) | D17: Feet | E17: TEM 2N Secondary Clarifier | F17: =IF(AND(G17>=0.291,G17<0.625),"7 to 3",IF(AND(G17>=0.625,G17<0.958334),"3 to 11",IF(G17>=0.958334,"11 to 7",IF(G17<0.291,"11 to 7","")))) -> #VALUE! | G17: =VALUE(Various!$B$17) -> #VALUE!
A18: =Various!#REF! -> #REF! | B18: Blankets | C18: =IF(Various!E16="","",Various!E16) | D18: Feet | E18: TEM 2N Secondary Clarifier | F18: 7 to 3 | G18: =VALUE(Various!$B$17) -> #VALUE!
A19: =Various!#REF! -> #REF! | B19: Blankets | C19: =IF(Various!E17="","",Various!E17) | D19: Feet | E19: TEM 2N Secondary Clarifier | F19: =IF(AND(G19>=0.291,G19<0.625),"7 to 3",IF(AND(G19>=0.625,G19<0.958334),"3 to 11",IF(G19>=0.958334,"11 to 7",IF(G19<0.291,"11 to 7","")))) -> #VALUE! | G19: =VALUE(Various!$B$17) -> #VALUE!
A20: =Various!#REF! -> #REF! | B20: Blankets | C20: =IF(Various!F15="","",Various!F15) | D20: Feet | E20: TEM 3N Secondary Clarifier | F20: =IF(AND(G20>=0.291,G20<0.625),"7 to 3",IF(AND(G20>=0.625,G20<0.958334),"3 to 11",IF(G20>=0.958334,"11 to 7",IF(G20<0.291,"11 to 7","")))) -> #VALUE! | G20: =VALUE(Various!$B$17) -> #VALUE!
A21: =Various!#REF! -> #REF! | B21: Blankets | C21: =IF(Various!F16="","",Various!F16) | D21: Feet | E21: TEM 3N Secondary Clarifier | F21: 7 to 3 | G21: =VALUE(Various!$B$17) -> #VALUE!
A22: =Various!#REF! -> #REF! | B22: Blankets | C22: =IF(Various!G17="","",Various!G17) | D22: Feet | E22: TEM 3N Secondary Clarifier | F22: =IF(AND(G22>=0.291,G22<0.625),"7 to 3",IF(AND(G22>=0.625,G22<0.958334),"3 to 11",IF(G22>=0.958334,"11 to 7",IF(G22<0.291,"11 to 7","")))) -> #VALUE! | G22: =VALUE(Various!$B$17) -> #VALUE!
A23: =Various!#REF! -> #REF! | B23: Blankets | C23: =IF(Various!G15="","",Various!G15) | D23: Feet | E23: TEM 4N Secondary Clarifier | F23: =IF(AND(G23>=0.291,G23<0.625),"7 to 3",IF(AND(G23>=0.625,G23<0.958334),"3 to 11",IF(G23>=0.958334,"11 to 7",IF(G23<0.291,"11 to 7","")))) -> #VALUE! | G23: =VALUE(Various!$B$17) -> #VALUE!
A24: =Various!#REF! -> #REF! | B24: Blankets | C24: =IF(Various!G16="","",Various!G16) | D24: Feet | E24: TEM 4N Secondary Clarifier | F24: 7 to 3 | G24: =VALUE(Various!$B$17) -> #VALUE!
A25: =Various!#REF! -> #REF! | B25: Blankets | C25: =IF(Various!#REF!="","",Various!#REF!) -> #REF! | D25: Feet | E25: TEM 4N Secondary Clarifier | F25: =IF(AND(G25>=0.291,G25<0.625),"7 to 3",IF(AND(G25>=0.625,G25<0.958334),"3 to 11",IF(G25>=0.958334,"11 to 7",IF(G25<0.291,"11 to 7","")))) -> #VALUE! | G25: =VALUE(Various!$B$17) -> #VALUE!
A26: =Various!#REF! -> #REF! | B26: Blankets | C26: =IF(Various!I15="","",Various!I15) | D26: Feet | E26: TEM 1S Secondary Clarifier | F26: =IF(AND(G26>=0.291,G26<0.625),"7 to 3",IF(AND(G26>=0.625,G26<0.958334),"3 to 11",IF(G26>=0.958334,"11 to 7",IF(G26<0.291,"11 to 7","")))) -> #VALUE! | G26: =VALUE(Various!$B$17) -> #VALUE!
A27: =Various!#REF! -> #REF! | B27: Blankets | C27: =IF(Various!I16="","",Various!I16) | D27: Feet | E27: TEM 1S Secondary Clarifier | F27: 7 to 3 | G27: =VALUE(Various!$B$17) -> #VALUE!
A28: =Various!#REF! -> #REF! | B28: Blankets | C28: =IF(Various!I17="","",Various!I17) | D28: Feet | E28: TEM 1S Secondary Clarifier | F28: =IF(AND(G28>=0.291,G28<0.625),"7 to 3",IF(AND(G28>=0.625,G28<0.958334),"3 to 11",IF(G28>=0.958334,"11 to 7",IF(G28<0.291,"11 to 7","")))) -> #VALUE! | G28: =VALUE(Various!$B$17) -> #VALUE!
A29: =Various!#REF! -> #REF! | B29: Blankets | C29: =IF(Various!K15="","",Various!K15) | D29: Feet | E29: TEM 2S Secondary Clarifier | F29: =IF(AND(G29>=0.291,G29<0.625),"7 to 3",IF(AND(G29>=0.625,G29<0.958334),"3 to 11",IF(G29>=0.958334,"11 to 7",IF(G29<0.291,"11 to 7","")))) -> #VALUE! | G29: =VALUE(Various!$B$17) -> #VALUE!
A30: =Various!#REF! -> #REF! | B30: Blankets | C30: =IF(Various!J16="","",Various!J16) | D30: Feet | E30: TEM 2S Secondary Clarifier | F30: 7 to 3 | G30: =VALUE(Various!$B$17) -> #VALUE!
A31: =Various!#REF! -> #REF! | B31: Blankets | C31: =IF(Various!J17="","",Various!J17) | D31: Feet | E31: TEM 2S Secondary Clarifier | F31: =IF(AND(G31>=0.291,G31<0.625),"7 to 3",IF(AND(G31>=0.625,G31<0.958334),"3 to 11",IF(G31>=0.958334,"11 to 7",IF(G31<0.291,"11 to 7","")))) -> #VALUE! | G31: =VALUE(Various!$B$17) -> #VALUE!
A32: =Various!#REF! -> #REF! | B32: Blankets | C32: =IF(Various!K15="","",Various!K15) | D32: Feet | E32: TEM 3S Secondary Clarifier | F32: =IF(AND(G32>=0.291,G32<0.625),"7 to 3",IF(AND(G32>=0.625,G32<0.958334),"3 to 11",IF(G32>=0.958334,"11 to 7",IF(G32<0.291,"11 to 7","")))) -> #VALUE! | G32: =VALUE(Various!$B$17) -> #VALUE!
A33: =Various!#REF! -> #REF! | B33: Blankets | C33: =IF(Various!K16="","",Various!K16) | D33: Feet | E33: TEM 3S Secondary Clarifier | F33: 7 to 3 | G33: =VALUE(Various!$B$17) -> #VALUE!
A34: =Various!#REF! -> #REF! | B34: Blankets | C34: =IF(Various!K17="","",Various!K17) | D34: Feet | E34: TEM 3S Secondary Clarifier | F34: =IF(AND(G34>=0.291,G34<0.625),"7 to 3",IF(AND(G34>=0.625,G34<0.958334),"3 to 11",IF(G34>=0.958334,"11 to 7",IF(G34<0.291,"11 to 7","")))) -> #VALUE! | G34: =VALUE(Various!$B$17) -> #VALUE!
A35: =Various!#REF! -> #REF! | B35: Blankets | C35: =IF(Various!L15="","",Various!L15) | D35: Feet | E35: TEM 4S Secondary Clarifier | F35: =IF(AND(G35>=0.291,G35<0.625),"7 to 3",IF(AND(G35>=0.625,G35<0.958334),"3 to 11",IF(G35>=0.958334,"11 to 7",IF(G35<0.291,"11 to 7","")))) -> #VALUE! | G35: =VALUE(Various!$B$17) -> #VALUE!
A36: =Various!#REF! -> #REF! | B36: Blankets | C36: =IF(Various!L16="","",Various!L16) | D36: Feet | E36: TEM 4S Secondary Clarifier | F36: 7 to 3 | G36: =VALUE(Various!$B$17) -> #VALUE!
A37: =Various!#REF! -> #REF! | B37: Blankets | C37: =IF(Various!L17="","",Various!L17) | D37: Feet | E37: TEM 4S Secondary Clarifier | F37: =IF(AND(G37>=0.291,G37<0.625),"7 to 3",IF(AND(G37>=0.625,G37<0.958334),"3 to 11",IF(G37>=0.958334,"11 to 7",IF(G37<0.291,"11 to 7","")))) -> #VALUE! | G37: =VALUE(Various!$B$17) -> #VALUE!
A38: =Various!#REF! -> #REF! | B38: Status | E38: TEM Flare #1 | F38: 7 to 3 | G38: =NOW()-ROUNDDOWN(NOW(),0) -> 0.70812859
A39: =Various!#REF! -> #REF! | B39: Status | E39: TEM Flare #1 | F39: 3 to 11 | G39: =NOW()-ROUNDDOWN(NOW(),0) -> 0.70812859
A40: =Various!#REF! -> #REF! | B40: Status | E40: TEM Flare #1 | F40: 11 to 7 | G40: =NOW()-ROUNDDOWN(NOW(),0) -> 0.70812859
...

Sheet How
B2: Color | C2: Meaning
C3: Do not edit directly
C4: Referenced on Print page
B8: ** All manually-entered times must be entered in HH:MM format military time
